Traceback (most recent call last):
  File "/home/runner/.cache/pypoetry/virtualenvs/mtbp3cd-OLnEGR1N-py3.10/lib/python3.10/site-packages/jupyter_core/utils/__init__.py", line 154, in wrapped
    asyncio.get_running_loop()
RuntimeError: no running event loop

During handling of the above exception, another exception occurred:

Traceback (most recent call last):
  File "/home/runner/.cache/pypoetry/virtualenvs/mtbp3cd-OLnEGR1N-py3.10/lib/python3.10/site-packages/jupyter_cache/executors/utils.py", line 58, in single_nb_execution
    executenb(
  File "/home/runner/.cache/pypoetry/virtualenvs/mtbp3cd-OLnEGR1N-py3.10/lib/python3.10/site-packages/nbclient/client.py", line 1319, in execute
    return NotebookClient(nb=nb, resources=resources, km=km, **kwargs).execute()
  File "/home/runner/.cache/pypoetry/virtualenvs/mtbp3cd-OLnEGR1N-py3.10/lib/python3.10/site-packages/jupyter_core/utils/__init__.py", line 158, in wrapped
    return loop.run_until_complete(inner)
  File "/opt/hostedtoolcache/Python/3.10.18/x64/lib/python3.10/asyncio/base_events.py", line 649, in run_until_complete
    return future.result()
  File "/home/runner/.cache/pypoetry/virtualenvs/mtbp3cd-OLnEGR1N-py3.10/lib/python3.10/site-packages/nbclient/client.py", line 709, in async_execute
    await self.async_execute_cell(
  File "/home/runner/.cache/pypoetry/virtualenvs/mtbp3cd-OLnEGR1N-py3.10/lib/python3.10/site-packages/nbclient/client.py", line 1062, in async_execute_cell
    await self._check_raise_for_error(cell, cell_index, exec_reply)
  File "/home/runner/.cache/pypoetry/virtualenvs/mtbp3cd-OLnEGR1N-py3.10/lib/python3.10/site-packages/nbclient/client.py", line 918, in _check_raise_for_error
    raise CellExecutionError.from_cell_and_msg(cell, exec_reply_content)
nbclient.exceptions.CellExecutionError: An error occurred while executing the following cell:
------------------
(crosstab_from_lists(df, rows, cols))['count']

------------------


[0;31m---------------------------------------------------------------------------[0m
[0;31mAttributeError[0m                            Traceback (most recent call last)
Cell [0;32mIn[3], line 1[0m
[0;32m----> 1[0m ([43mcrosstab_from_lists[49m[43m([49m[43mdf[49m[43m,[49m[43m [49m[43mrows[49m[43m,[49m[43m [49m[43mcols[49m[43m)[49m)[[38;5;124m'[39m[38;5;124mcount[39m[38;5;124m'[39m]

File [0;32m~/work/mtbp3cd/mtbp3cd/mtbp3cd/util/gt03summary.py:78[0m, in [0;36mcrosstab_from_lists[0;34m(df, rows, cols, perct_within_index, col_margin_perct, row_margin_perct, report_type)[0m
[1;32m     76[0m [38;5;28;01mif[39;00m [38;5;129;01mnot[39;00m [38;5;28mall[39m(col [38;5;129;01min[39;00m df[38;5;241m.[39mcolumns [38;5;28;01mfor[39;00m col [38;5;129;01min[39;00m cols):
[1;32m     77[0m     [38;5;28;01mraise[39;00m [38;5;167;01mValueError[39;00m([38;5;124m"[39m[38;5;124mAll elements in [39m[38;5;124m'[39m[38;5;124mcols[39m[38;5;124m'[39m[38;5;124m must be column names of df.[39m[38;5;124m"[39m)
[0;32m---> 78[0m [38;5;28;01mif[39;00m [43mrows[49m[38;5;241;43m.[39;49m[43mintersection[49m(cols):
[1;32m     79[0m     [38;5;28;01mraise[39;00m [38;5;167;01mValueError[39;00m([38;5;124m"[39m[38;5;124mThe intersection of [39m[38;5;124m'[39m[38;5;124mrows[39m[38;5;124m'[39m[38;5;124m and [39m[38;5;124m'[39m[38;5;124mcols[39m[38;5;124m'[39m[38;5;124m must be empty.[39m[38;5;124m"[39m)
[1;32m     80[0m [38;5;66;03m# s.2[39;00m

[0;31mAttributeError[0m: 'list' object has no attribute 'intersection'

