Traceback (most recent call last):
  File "/home/runner/.cache/pypoetry/virtualenvs/mtbp3cd-OLnEGR1N-py3.10/lib/python3.10/site-packages/jupyter_core/utils/__init__.py", line 154, in wrapped
    asyncio.get_running_loop()
RuntimeError: no running event loop

During handling of the above exception, another exception occurred:

Traceback (most recent call last):
  File "/home/runner/.cache/pypoetry/virtualenvs/mtbp3cd-OLnEGR1N-py3.10/lib/python3.10/site-packages/jupyter_cache/executors/utils.py", line 58, in single_nb_execution
    executenb(
  File "/home/runner/.cache/pypoetry/virtualenvs/mtbp3cd-OLnEGR1N-py3.10/lib/python3.10/site-packages/nbclient/client.py", line 1319, in execute
    return NotebookClient(nb=nb, resources=resources, km=km, **kwargs).execute()
  File "/home/runner/.cache/pypoetry/virtualenvs/mtbp3cd-OLnEGR1N-py3.10/lib/python3.10/site-packages/jupyter_core/utils/__init__.py", line 158, in wrapped
    return loop.run_until_complete(inner)
  File "/opt/hostedtoolcache/Python/3.10.18/x64/lib/python3.10/asyncio/base_events.py", line 649, in run_until_complete
    return future.result()
  File "/home/runner/.cache/pypoetry/virtualenvs/mtbp3cd-OLnEGR1N-py3.10/lib/python3.10/site-packages/nbclient/client.py", line 709, in async_execute
    await self.async_execute_cell(
  File "/home/runner/.cache/pypoetry/virtualenvs/mtbp3cd-OLnEGR1N-py3.10/lib/python3.10/site-packages/nbclient/client.py", line 1062, in async_execute_cell
    await self._check_raise_for_error(cell, cell_index, exec_reply)
  File "/home/runner/.cache/pypoetry/virtualenvs/mtbp3cd-OLnEGR1N-py3.10/lib/python3.10/site-packages/nbclient/client.py", line 918, in _check_raise_for_error
    raise CellExecutionError.from_cell_and_msg(cell, exec_reply_content)
nbclient.exceptions.CellExecutionError: An error occurred while executing the following cell:
------------------
import mtbp3cd.util.gt03summary
------------------


[0;31m---------------------------------------------------------------------------[0m
[0;31mModuleNotFoundError[0m                       Traceback (most recent call last)
Cell [0;32mIn[1], line 1[0m
[0;32m----> 1[0m [38;5;28;01mimport[39;00m[38;5;250m [39m[38;5;21;01mmtbp3cd[39;00m[38;5;21;01m.[39;00m[38;5;21;01mutil[39;00m[38;5;21;01m.[39;00m[38;5;21;01mgt03summary[39;00m

File [0;32m~/work/mtbp3cd/mtbp3cd/mtbp3cd/__init__.py:1[0m
[0;32m----> 1[0m [38;5;28;01mfrom[39;00m[38;5;250m [39m[38;5;21;01m.[39;00m[38;5;21;01mgui[39;00m[38;5;250m [39m[38;5;28;01mimport[39;00m [38;5;241m*[39m
[1;32m      2[0m [38;5;28;01mfrom[39;00m[38;5;250m [39m[38;5;21;01m.[39;00m[38;5;21;01mutil[39;00m[38;5;250m [39m[38;5;28;01mimport[39;00m [38;5;241m*[39m
[1;32m      4[0m [38;5;28;01mfrom[39;00m[38;5;250m [39m[38;5;21;01mimportlib[39;00m[38;5;21;01m.[39;00m[38;5;21;01mmetadata[39;00m[38;5;250m [39m[38;5;28;01mimport[39;00m version

File [0;32m~/work/mtbp3cd/mtbp3cd/mtbp3cd/gui/__init__.py:2[0m
[1;32m      1[0m [38;5;28;01mimport[39;00m[38;5;250m [39m[38;5;21;01msys[39;00m
[0;32m----> 2[0m [38;5;28;01mfrom[39;00m[38;5;250m [39m[38;5;21;01mPyQt6[39;00m[38;5;21;01m.[39;00m[38;5;21;01mQtWidgets[39;00m[38;5;250m [39m[38;5;28;01mimport[39;00m QApplication
[1;32m      3[0m [38;5;28;01mfrom[39;00m[38;5;250m [39m[38;5;21;01m.[39;00m[38;5;21;01mappfileinventory[39;00m[38;5;250m [39m[38;5;28;01mimport[39;00m [38;5;241m*[39m
[1;32m      4[0m [38;5;28;01mfrom[39;00m[38;5;250m [39m[38;5;21;01m.[39;00m[38;5;21;01mappclinicaldata[39;00m[38;5;250m [39m[38;5;28;01mimport[39;00m [38;5;241m*[39m

[0;31mModuleNotFoundError[0m: No module named 'PyQt6'

